Workbook

Sheet Listado Unificado de Parcelas
A1: N° | B1: Circunscripción | C1: Sección | D1: Manzana | E1: Parcela | F1: Partida ARBA | G1: Partida Municipal | H1: Escritura | I1: Matrícula / Folio | J1: Certificado Catastral | K1: Valuación Fiscal | L1: VF al Acto | M1: Superficie M2 | N1: Estado | O1: Precio Etapa 1 | P1: Valor / m2 | Q1: Anticipo % | R1: Tasa mensual | S1: Anticipo USD | T1: Saldo USD | U1: 48 cuotas de | V1: 60 cuotas de | W1: Nota
A2: 1 | B2: 5 | C2: F | D2: 1 | E2: 1 | F2: 199468 | G2: 46662 | H2: 442 | I2: 74463 | J2: 24495422 | K2: 94248 | L2: 2340837 | M2: =+_xlfn.XLOOKUP(D2&"-"&E2,'[1]Listado Lotes'!$K$3:$K$385,'[1]Listado Lotes'!$E$3:$E$385) -> 230.52 | N2: NO DISPONIBLE | O2: #N/A | P2: #N/A | Q2: #N/A | R2: #N/A | S2: #N/A | T2: #N/A | W2: #N/A
A3: 2 | B3: 5 | C3: F | D3: 1 | E3: 2 | F3: 199469 | G3: 46663 | H3: 442 | I3: 74464 | J3: 24495426 | K3: 95472 | L3: 2371238 | M3: =+_xlfn.XLOOKUP(D3&"-"&E3,'[1]Listado Lotes'!$K$3:$K$385,'[1]Listado Lotes'!$E$3:$E$385) -> 233.98 | N3: NO DISPONIBLE | O3: #N/A | P3: #N/A | Q3: #N/A | R3: #N/A | S3: #N/A | T3: #N/A | W3: #N/A
A4: 3 | B4: 5 | C4: F | D4: 1 | E4: 3 | F4: 199470 | G4: 46664 | H4: 442 | I4: 74465 | J4: 24495433 | K4: 75114 | L4: 1865606 | M4: =+_xlfn.XLOOKUP(D4&"-"&E4,'[1]Listado Lotes'!$K$3:$K$385,'[1]Listado Lotes'!$E$3:$E$385) -> 233.98 | N4: NO DISPONIBLE | O4: #N/A | P4: #N/A | Q4: #N/A | R4: #N/A | S4: #N/A | T4: #N/A | W4: #N/A
A5: 4 | B5: 5 | C5: F | D5: 1 | E5: 4 | F5: 199471 | G5: 46665 | H5: 442 | I5: 74466 | J5: 24495436 | K5: 75114 | L5: 1865606 | M5: =+_xlfn.XLOOKUP(D5&"-"&E5,'[1]Listado Lotes'!$K$3:$K$385,'[1]Listado Lotes'!$E$3:$E$385) -> 233.98 | N5: NO DISPONIBLE | O5: #N/A | P5: #N/A | Q5: #N/A | R5: #N/A | S5: #N/A | T5: #N/A | W5: #N/A
A6: 5 | B6: 5 | C6: F | D6: 1 | E6: 5 | F6: 199472 | G6: 46666 | H6: 442 | I6: 74467 | J6: 24495439 | K6: 75114 | L6: 1865606 | M6: =+_xlfn.XLOOKUP(D6&"-"&E6,'[1]Listado Lotes'!$K$3:$K$385,'[1]Listado Lotes'!$E$3:$E$385) -> 233.98 | N6: NO DISPONIBLE | O6: #N/A | P6: #N/A | Q6: #N/A | R6: #N/A | S6: #N/A | T6: #N/A | W6: #N/A
A7: 6 | B7: 5 | C7: F | D7: 1 | E7: 6 | F7: 199473 | G7: 46667 | H7: 442 | I7: 74468 | J7: 24495443 | K7: 75114 | L7: 1865606 | M7: =+_xlfn.XLOOKUP(D7&"-"&E7,'[1]Listado Lotes'!$K$3:$K$385,'[1]Listado Lotes'!$E$3:$E$385) -> 233.98 | N7: NO DISPONIBLE | O7: #N/A | P7: #N/A | Q7: #N/A | R7: #N/A | S7: #N/A | T7: #N/A | W7: #N/A
A8: 7 | B8: 5 | C8: F | D8: 1 | E8: 7 | F8: 199474 | G8: 46668 | H8: 442 | I8: 74469 | J8: 24495802 | K8: 98241 | L8: 2440026 | M8: =+_xlfn.XLOOKUP(D8&"-"&E8,'[1]Listado Lotes'!$K$3:$K$385,'[1]Listado Lotes'!$E$3:$E$385) -> 229.5 | N8: NO DISPONIBLE | O8: #N/A | P8: #N/A | Q8: #N/A | R8: #N/A | S8: #N/A | T8: #N/A | W8: #N/A
A9: 8 | B9: 5 | C9: F | D9: 1 | E9: 8 | F9: 199475 | G9: 44932 | H9: 442 | I9: 74992 | J9: 24495786 | K9: 107460 | L9: 2668984 | M9: =+_xlfn.XLOOKUP(D9&"-"&E9,'[1]Listado Lotes'!$K$3:$K$385,'[1]Listado Lotes'!$E$3:$E$385) -> 398.26 | N9: NO DISPONIBLE | O9: #N/A | P9: #N/A | Q9: #N/A | R9: #N/A | S9: #N/A | T9: #N/A | W9: #N/A
A10: 9 | B10: 5 | C10: F | D10: 1 | E10: 9 | F10: 199476 | G10: 46669 | H10: 442 | I10: 74470 | J10: 24495795 | K10: 107460 | L10: 2668984 | M10: =+_xlfn.XLOOKUP(D10&"-"&E10,'[1]Listado Lotes'!$K$3:$K$385,'[1]Listado Lotes'!$E$3:$E$385) -> 398.26 | N10: NO DISPONIBLE | O10: #N/A | P10: #N/A | Q10: #N/A | R10: #N/A | S10: #N/A | T10: #N/A | W10: #N/A
A11: 10 | B11: 5 | C11: F | D11: 1 | E11: 10 | F11: 199477 | G11: 46670 | H11: 442 | I11: 74471 | J11: 24495894 | K11: 107460 | L11: 2668984 | M11: =+_xlfn.XLOOKUP(D11&"-"&E11,'[1]Listado Lotes'!$K$3:$K$385,'[1]Listado Lotes'!$E$3:$E$385) -> 398.26 | N11: NO DISPONIBLE | O11: #N/A | P11: #N/A | Q11: #N/A | R11: #N/A | S11: #N/A | T11: #N/A | W11: #N/A
A12: 11 | B12: 5 | C12: F | D12: 1 | E12: 11 | F12: 199478 | G12: 46671 | H12: 442 | I12: 74472 | J12: 24495897 | K12: 107460 | L12: 2668984 | M12: =+_xlfn.XLOOKUP(D12&"-"&E12,'[1]Listado Lotes'!$K$3:$K$385,'[1]Listado Lotes'!$E$3:$E$385) -> 398.26 | N12: NO DISPONIBLE | O12: #N/A | P12: #N/A | Q12: #N/A | R12: #N/A | S12: #N/A | T12: #N/A | W12: #N/A
A13: 12 | B13: 5 | C13: F | D13: 1 | E13: 12 | F13: 199479 | G13: 466672 | H13: 442 | I13: 74474 | J13: 24495902 | K13: 107460 | L13: 2668984 | M13: =+_xlfn.XLOOKUP(D13&"-"&E13,'[1]Listado Lotes'!$K$3:$K$385,'[1]Listado Lotes'!$E$3:$E$385) -> 398.26 | N13: NO DISPONIBLE | O13: #N/A | P13: #N/A | Q13: #N/A | R13: #N/A | S13: #N/A | T13: #N/A | W13: #N/A
... A61: 60 | B61: 5 | C61: F | D61: 2 | E61: 28 | F61: 199242 | G61: 46719 | H61: 442 | I61: 74554 | J61: 24491949 | K61: 89700 | L61: 2227878 | M61: =+_xlfn.XLOOKUP(D61&"-"&E61,'[1]Listado Lotes'!$K$3:$K$385,'[1]Listado Lotes'!$E$3:$E$385) -> 298.69 | N61: NO DISPONIBLE | O61: #N/A | P61: #N/A | Q61: #N/A | R61: #N/A | S61: #N/A | T61: #N/A | W61: #N/A
A62: 61 | B62: 5 | C62: F | D62: 3 | E62: 1 | F62: 199500 | G62: 46720 | H62: 442 | I62: 74437 | J62: 24491950 | K62: 98241 | L62: 2440026 | M62: =+_xlfn.XLOOKUP(D62&"-"&E62,'[1]Listado Lotes'!$K$3:$K$385,'[1]Listado Lotes'!$E$3:$E$385) -> 229.5 | N62: PUBLICADO | O62: 15000 | P62: 65.502183 | Q62: 0.3 | R62: 0.01 | S62: 4500 | T62: 10500 | U62: 323.75 | V62: 280 | W62: Laterales chicos, sobre Richieri
A63: 62 | B63: 5 | C63: F | D63: 3 | E63: 2 | F63: 199501 | G63: 46721 | H63: 442 | I63: 74438 | J63: 24491951 | K63: 75114 | L63: 1865606 | M63: =+_xlfn.XLOOKUP(D63&"-"&E63,'[1]Listado Lotes'!$K$3:$K$385,'[1]Listado Lotes'!$E$3:$E$385) -> 233.98 | N63: PUBLICADO | O63: 15000 | P63: 64.102564 | Q63: 0.3 | R63: 0.01 | S63: 4500 | T63: 10500 | U63: 323.75 | V63: 280 | W63: Laterales chicos, sobre Richieri
A64: 63 | B64: 5 | C64: F | D64: 3 | E64: 4 | F64: 199503 | G64: 46723 | H64: 442 | I64: 74439 | J64: 24491953 | K64: 75114 | L64: 1865606 | M64: =+_xlfn.XLOOKUP(D64&"-"&E64,'[1]Listado Lotes'!$K$3:$K$385,'[1]Listado Lotes'!$E$3:$E$385) -> 233.98 | N64: PUBLICADO | O64: 15000 | P64: 64.102564 | Q64: 0.3 | R64: 0.01 | S64: 4500 | T64: 10500 | U64: 323.75 | V64: 280 | W64: Laterales chicos, sobre Richieri
A65: 64 | B65: 5 | C65: F | D65: 3 | E65: 5 | F65: 199504 | G65: 46724 | H65: 442 | I65: 74440 | J65: 24491954 | K65: 75114 | L65: 1865606 | M65: =+_xlfn.XLOOKUP(D65&"-"&E65,'[1]Listado Lotes'!$K$3:$K$385,'[1]Listado Lotes'!$E$3:$E$385) -> 233.98 | N65: PUBLICADO | O65: 15000 | P65: 64.102564 | Q65: 0.3 | R65: 0.01 | S65: 4500 | T65: 10500 | U65: 323.75 | V65: 280 | W65: Laterales chicos, sobre Richieri
A66: 65 | B66: 5 | C66: F | D66: 3 | E66: 6 | F66: 199505 | G66: 46725 | H66: 442 | I66: 74441 | J66: 24491956 | K66: 98241 | L66: 2440026 | M66: =+_xlfn.XLOOKUP(D66&"-"&E66,'[1]Listado Lotes'!$K$3:$K$385,'[1]Listado Lotes'!$E$3:$E$385) -> 229.5 | N66: PUBLICADO | O66: 15000 | P66: 65.502183 | Q66: 0.3 | R66: 0.01 | S66: 4500 | T66: 10500 | U66: 323.75 | V66: 280 | W66: Laterales chicos, sobre Richieri
A67: 66 | B67: 5 | C67: F | D67: 3 | E67: 7 | F67: 199506 | G67: 46726 | H67: 442 | I67: 74442 | J67: 24491957 | K67: 89700 | L67: 2227878 | M67: =+_xlfn.XLOOKUP(D67&"-"&E67,'[1]Listado Lotes'!$K$3:$K$385,'[1]Listado Lotes'!$E$3:$E$385) -> 298.69 | N67: PUBLICADO | O67: 15000 | P67: 50.167224 | Q67: 0.3 | R67: 0.01 | S67: 4500 | T67: 10500 | U67: 323.75 | V67: 280 | W67: Verticales medianos
A68: 67 | B68: 5 | C68: F | D68: 3 | E68: 8 | F68: 199507 | G68: 46727 | H68: 442 | I68: 74443 | J68: 24491958 | K68: 89700 | L68: 2227878 | M68: =+_xlfn.XLOOKUP(D68&"-"&E68,'[1]Listado Lotes'!$K$3:$K$385,'[1]Listado Lotes'!$E$3:$E$385) -> 298.69 | N68: PUBLICADO | O68: 15000 | P68: 50.167224 | Q68: 0.3 | R68: 0.01 | S68: 4500 | T68: 10500 | U68: 323.75 | V68: 280 | W68: Verticales medianos
A69: 68 | B69: 5 | C69: F | D69: 3 | E69: 9 | F69: 199508 | G69: 46728 | H69: 442 | I69: 74444 | J69: 24491959 | K69: 89700 | L69: 2227878 | M69: =+_xlfn.XLOOKUP(D69&"-"&E69,'[1]Listado Lotes'!$K$3:$K$385,'[1]Listado Lotes'!$E$3:$E$385) -> 298.69 | N69: PUBLICADO | O69: 15000 | P69: 50.167224 | Q69: 0.3 | R69: 0.01 | S69: 4500 | T69: 10500 | U69: 323.75 | V69: 280 | W69: Verticales medianos
A70: 69 | B70: 5 | C70: F | D70: 3 | E70: 10 | F70: 199509 | G70: 6620-2 | H70: 442 | I70: 74445 | J70: 24491960 | K70: 89700 | L70: 2227878 | M70: =+_xlfn.XLOOKUP(D70&"-"&E70,'[1]Listado Lotes'!$K$3:$K$385,'[1]Listado Lotes'!$E$3:$E$385) -> 298.69 | N70: PUBLICADO | O70: 15000 | P70: 50.167224 | Q70: 0.3 | R70: 0.01 | S70: 4500 | T70: 10500 | U70: 323.75 | V70: 280 | W70: Verticales medianos
A71: 70 | B71: 5 | C71: F | D71: 3 | E71: 11 | F71: 199510 | G71: 46729 | H71: 442 | I71: 74446 | J71: 24491961 | K71: 89700 | L71: 2227878 | M71: =+_xlfn.XLOOKUP(D71&"-"&E71,'[1]Listado Lotes'!$K$3:$K$385,'[1]Listado Lotes'!$E$3:$E$385) -> 298.69 | N71: PUBLICADO | O71: 15000 | P71: 50.167224 | Q71: 0.3 | R71: 0.01 | S71: 4500 | T71: 10500 | U71: 323.75 | V71: 280 | W71: Verticales medianos
A72: 71 | B72: 5 | C72: F | D72: 3 | E72: 12 | F72: 199511 | G72: 46730 | H72: 442 | I72: 74447 | J72: 24491962 | K72: 89700 | L72: 2227878 | M72: =+_xlfn.XLOOKUP(D72&"-"&E72,'[1]Listado Lotes'!$K$3:$K$385,'[1]Listado Lotes'!$E$3:$E$385) -> 298.69 | N72: PUBLICADO | O72: 15000 | P72: 50.167224 | Q72: 0.3 | R72: 0.01 | S72: 4500 | T72: 10500 | U72: 323.75 | V72: 280 | W72: Verticales medianos
A73: 72 | B73: 5 | C73: F | D73: 3 | E73: 14 | F73: 199513 | G73: 46732 | H73: 442 | I73: 74448 | J73: 24491965 | K73: 89700 | L73: 2227878 | M73: =+_xlfn.XLOOKUP(D73&"-"&E73,'[1]Listado Lotes'!$K$3:$K$385,'[1]Listado Lotes'!$E$3:$E$385) -> 298.69 | N73: PUBLICADO | O73: 15000 | P73: 50.167224 | Q73: 0.3 | R73: 0.01 | S73: 4500 | T73: 10500 | U73: 323.75 | V73: 280 | W73: Verticales medianos
A74: 73 | B74: 5 | C74: F | D74: 3 | E74: 15 | F74: 199514 | G74: 46733 | H74: 442 | I74: 74449 | J74: 24491966 | K74: 98241 | L74: 2440026 | M74: =+_xlfn.XLOOKUP(D74&"-"&E74,'[1]Listado Lotes'!$K$3:$K$385,'[1]Listado Lotes'!$E$3:$E$385) -> 229.5 | N74: PUBLICADO | O74: 13500 | P74: 58.951965 | Q74: 0.3 | R74: 0.01 | S74: 4050 | T74: 9450 | U74: 291.375 | V74: 252 | W74: Laterales chicos sobre Patricias Argentinas
A75: 74 | B75: 5 | C75: F | D75: 3 | E75: 16 | F75: 199515 | G75: 46734 | H75: 442 | I75: 74450 | J75: 24491967 | K75: 75114 | L75: 1865606 | M75: =+_xlfn.XLOOKUP(D75&"-"&E75,'[1]Listado Lotes'!$K$3:$K$385,'[1]Listado Lotes'!$E$3:$E$385) -> 233.98 | N75: PUBLICADO | O75: 13500 | P75: 57.692308 | Q75: 0.3 | R75: 0.01 | S75: 4050 | T75: 9450 | U75: 291.375 | V75: 252 | W75: Laterales chicos sobre Patricias Argentinas
A76: 75 | B76: 5 | C76: F | D76: 3 | E76: 17 | F76: 199516 | G76: 46735 | H76: 442 | I76: 74451 | J76: 24491968 | K76: 75114 | L76: 1865606 | M76: =+_xlfn.XLOOKUP(D76&"-"&E76,'[1]Listado Lotes'!$K$3:$K$385,'[1]Listado Lotes'!$E$3:$E$385) -> 233.98 | N76: PUBLICADO | O76: 13500 | P76: 57.692308 | Q76: 0.3 | R76: 0.01 | S76: 4050 | T76: 9450 | U76: 291.375 | V76: 252 | W76: Laterales chicos sobre Patricias Argentinas
A77: 76 | B77: 5 | C77: F | D77: 3 | E77: 18 | F77: 199517 | G77: 46736 | H77: 442 | I77: 74452 | J77: 24491970 | K77: 75114 | L77: 1865606 | M77: =+_xlfn.XLOOKUP(D77&"-"&E77,'[1]Listado Lotes'!$K$3:$K$385,'[1]Listado Lotes'!$E$3:$E$385) -> 233.98 | N77: PUBLICADO | O77: 13500 | P77: 57.692308 | Q77: 0.3 | R77: 0.01 | S77: 4050 | T77: 9450 | U77: 291.375 | V77: 252 | W77: Laterales chicos sobre Patricias Argentinas
A78: 77 | B78: 5 | C78: F | D78: 3 | E78: 19 | F78: 199518 | G78: 46737 | H78: 442 | I78: 74453 | J78: 24491971 | K78: 75114 | L78: 1865606 | M78: =+_xlfn.XLOOKUP(D78&"-"&E78,'[1]Listado Lotes'!$K$3:$K$385,'[1]Listado Lotes'!$E$3:$E$385) -> 233.98 | N78: PUBLICADO | O78: 13500 | P78: 57.692308 | Q78: 0.3 | R78: 0.01 | S78: 4050 | T78: 9450 | U78: 291.375 | V78: 252 | W78: Laterales chicos sobre Patricias Argentinas
A79: 78 | B79: 5 | C79: F | D79: 3 | E79: 20 | F79: 199519 | G79: 46738 | H79: 442 | I79: 74454 | J79: 24491972 | K79: 98241 | L79: 2440026 | M79: =+_xlfn.XLOOKUP(D79&"-"&E79,'[1]Listado Lotes'!$K$3:$K$385,'[1]Listado Lotes'!$E$3:$E$385) -> 229.5 | N79: PUBLICADO | O79: 13500 | P79: 58.951965 | Q79: 0.3 | R79: 0.01 | S79: 4050 | T79: 9450 | U79: 291.375 | V79: 252 | W79: Laterales chicos sobre Patricias Argentinas
A80: 79 | B80: 5 | C80: F | D80: 3 | E80: 21 | F80: 199520 | G80: 46739 | H80: 442 | I80: 74455 | J80: 24491973 | K80: 89700 | L80: 2227878 | M80: =+_xlfn.XLOOKUP(D80&"-"&E80,'[1]Listado Lotes'!$K$3:$K$385,'[1]Listado Lotes'!$E$3:$E$385) -> 298.69 | N80: PUBLICADO | O80: 15000 | P80: 50.167224 | Q80: 0.3 | R80: 0.01 | S80: 4500 | T80: 10500 | U80: 323.75 | V80: 280 | W80: Verticales medianos
A81: 80 | B81: 5 | C81: F | D81: 3 | E81: 22 | F81: 199521 | G81: 46740 | H81: 442 | I81: 74456 | J81: 24491974 | K81: 89700 | L81: 2227878 | M81: =+_xlfn.XLOOKUP(D81&"-"&E81,'[1]Listado Lotes'!$K$3:$K$385,'[1]Listado Lotes'!$E$3:$E$385) -> 298.69 | N81: PUBLICADO | O81: 15000 | P81: 50.167224 | Q81: 0.3 | R81: 0.01 | S81: 4500 | T81: 10500 | U81: 323.75 | V81: 280 | W81: Verticales medianos
A82: 81 | B82: 5 | C82: F | D82: 3 | E82: 23 | F82: 199522 | G82: 46741 | H82: 442 | I82: 74457 | J82: 24491975 | K82: 89700 | L82: 2227878 | M82: =+_xlfn.XLOOKUP(D82&"-"&E82,'[1]Listado Lotes'!$K$3:$K$385,'[1]Listado Lotes'!$E$3:$E$385) -> 298.69 | N82: PUBLICADO | O82: 15000 | P82: 50.167224 | Q82: 0.3 | R82: 0.01 | S82: 4500 | T82: 10500 | U82: 323.75 | V82: 280 | W82: Verticales medianos
... A87: 86 | B87: 5 | C87: F | D87: 3 | E87: 28 | F87: 199527 | G87: 46746 | H87: 442 | I87: 74462 | J87: 24491980 | K87: 89700 | L87: 2227878 | M87: =+_xlfn.XLOOKUP(D87&"-"&E87,'[1]Listado Lotes'!$K$3:$K$385,'[1]Listado Lotes'!$E$3:$E$385) -> 298.69 | N87: PUBLICADO | O87: 15000 | P87: 50.167224 | Q87: 0.3 | R87: 0.01 | S87: 4500 | T87: 10500 | U87: 323.75 | V87: 280 | W87: Verticales medianos
A88: 87 | B88: 5 | C88: F | D88: 31 | E88: 1 | F88: 199558 | G88: 46815 | H88: 442 | I88: 74484 | J88: 24492167 | K88: 99099 | L88: 2461336 | M88: =+_xlfn.XLOOKUP(D88&"-"&E88,'[1]Listado Lotes'!$K$3:$K$385,'[1]Listado Lotes'!$E$3:$E$385) -> 230.52 | N88: NO DISPONIBLE | O88: #N/A | P88: #N/A | Q88: #N/A | R88: #N/A | S88: #N/A | T88: #N/A | W88: #N/A
A89: 88 | B89: 5 | C89: F | D89: 31 | E89: 2 | F89: 199559 | G89: 46816 | H89: 442 | I89: 74485 | J89: 24492170 | K89: 75114 | L89: 1865606 | M89: =+_xlfn.XLOOKUP(D89&"-"&E89,'[1]Listado Lotes'!$K$3:$K$385,'[1]Listado Lotes'!$E$3:$E$385) -> 233.98 | N89: NO DISPONIBLE | O89: #N/A | P89: #N/A | Q89: #N/A | R89: #N/A | S89: #N/A | T89: #N/A | W89: #N/A
A90: 89 | B90: 5 | C90: F | D90: 31 | E90: 3 | F90: 199560 | G90: 46817 | H90: 442 | I90: 74486 | J90: 24492173 | K90: 75114 | L90: 1865606 | M90: =+_xlfn.XLOOKUP(D90&"-"&E90,'[1]Listado Lotes'!$K$3:$K$385,'[1]Listado Lotes'!$E$3:$E$385) -> 233.98 | N90: NO DISPONIBLE | O90: #N/A | P90: #N/A | Q90: #N/A | R90: #N/A | S90: #N/A | T90: #N/A | W90: #N/A
A91: 90 | B91: 5 | C91: F | D91: 31 | E91: 4 | F91: 199561 | G91: 46818 | H91: 442 | I91: 74487 | J91: 24492175 | K91: 75114 | L91: 1865606 | M91: =+_xlfn.XLOOKUP(D91&"-"&E91,'[1]Listado Lotes'!$K$3:$K$385,'[1]Listado Lotes'!$E$3:$E$385) -> 233.98 | N91: NO DISPONIBLE | O91: #N/A | P91: #N/A | Q91: #N/A | R91: #N/A | S91: #N/A | T91: #N/A | W91: #N/A
...

Sheet Original Lotes Escritura
A1: N° Hugo | B1: Circunscripción | C1: Sección | D1: Manzana | E1: Parcela | F1: Partida ARBA | G1: Partida Municipal | H1: Escritura | I1: Matrícula / Folio | J1: Certificado Catastral | K1: Valuación Fiscal | L1: VF al Acto
A2: 1 | B2: 1 | C2: 1 | E2: 1 | F2: 199468 | G2: 46662 | H2: 442 | I2: 74463 | J2: 24495422 | K2: 94248 | L2: 2340837
A3: 2 | B3: 1 | C3: 1 | E3: 2 | F3: 199469 | G3: 46663 | H3: 442 | I3: 74464 | J3: 24495426 | K3: 95472 | L3: 2371238
A4: 3 | B4: 1 | C4: 1 | E4: 3 | F4: 199470 | G4: 46664 | H4: 442 | I4: 74465 | J4: 24495433 | K4: 75114 | L4: 1865606
A5: 4 | B5: 1 | C5: 1 | E5: 4 | F5: 199471 | G5: 46665 | H5: 442 | I5: 74466 | J5: 24495436 | K5: 75114 | L5: 1865606
A6: 5 | B6: 1 | C6: 1 | E6: 5 | F6: 199472 | G6: 46666 | H6: 442 | I6: 74467 | J6: 24495439 | K6: 75114 | L6: 1865606
A7: 6 | B7: 1 | C7: 1 | E7: 6 | F7: 199473 | G7: 46667 | H7: 442 | I7: 74468 | J7: 24495443 | K7: 75114 | L7: 1865606
A8: 7 | B8: 1 | C8: 1 | E8: 7 | F8: 199474 | G8: 46668 | H8: 442 | I8: 74469 | J8: 24495802 | K8: 98241 | L8: 2440026
A9: 8 | B9: 1 | C9: 1 | E9: 8 | F9: 199475 | G9: 44932 | H9: 442 | I9: 74992 | J9: 24495786 | K9: 107460 | L9: 2668984
A10: 9 | B10: 1 | C10: 1 | E10: 9 | F10: 199476 | G10: 46669 | H10: 442 | I10: 74470 | J10: 24495795 | K10: 107460 | L10: 2668984
A11: 10 | B11: 1 | C11: 1 | E11: 10 | F11: 199477 | G11: 46670 | H11: 442 | I11: 74471 | J11: 24495894 | K11: 107460 | L11: 2668984
A12: 11 | B12: 1 | C12: 1 | E12: 11 | F12: 199478 | G12: 46671 | H12: 442 | I12: 74472 | J12: 24495897 | K12: 107460 | L12: 2668984
A13: 12 | B13: 1 | C13: 1 | E13: 12 | F13: 199479 | G13: 466672 | H13: 442 | I13: 74474 | J13: 24495902 | K13: 107460 | L13: 2668984
... A69: 68 | B69: 1 | C69: 3 | E69: 9 | F69: 199508 | G69: 46728 | H69: 442 | I69: 74444 | J69: 24491959 | K69: 89700 | L69: 2227878
A70: 69 | B70: 1 | C70: 3 | E70: 10 | F70: 199509 | G70: 6620-2 | H70: 442 | I70: 74445 | J70: 24491960 | K70: 89700 | L70: 2227878
A71: 70 | B71: 1 | C71: 3 | E71: 11 | F71: 199510 | G71: 46729 | H71: 442 | I71: 74446 | J71: 24491961 | K71: 89700 | L71: 2227878
A72: 71 | B72: 1 | C72: 3 | E72: 12 | F72: 199511 | G72: 46730 | H72: 442 | I72: 74447 | J72: 24491962 | K72: 89700 | L72: 2227878
A73: 72 | B73: 1 | C73: 3 | E73: 14 | F73: 199513 | G73: 46732 | H73: 442 | I73: 74448 | J73: 24491965 | K73: 89700 | L73: 2227878
A74: 73 | B74: 1 | C74: 3 | E74: 15 | F74: 199514 | G74: 46733 | H74: 442 | I74: 74449 | J74: 24491966 | K74: 98241 | L74: 2440026
A75: 74 | B75: 1 | C75: 3 | E75: 16 | F75: 199515 | G75: 46734 | H75: 442 | I75: 74450 | J75: 24491967 | K75: 75114 | L75: 1865606
A76: 75 | B76: 1 | C76: 3 | E76: 17 | F76: 199516 | G76: 46735 | H76: 442 | I76: 74451 | J76: 24491968 | K76: 75114 | L76: 1865606
A77: 76 | B77: 1 | C77: 3 | E77: 18 | F77: 199517 | G77: 46736 | H77: 442 | I77: 74452 | J77: 24491970 | K77: 75114 | L77: 1865606
A78: 77 | B78: 1 | C78: 3 | E78: 19 | F78: 199518 | G78: 46737 | H78: 442 | I78: 74453 | J78: 24491971 | K78: 75114 | L78: 1865606
A79: 78 | B79: 1 | C79: 3 | E79: 20 | F79: 199519 | G79: 46738 | H79: 442 | I79: 74454 | J79: 24491972 | K79: 98241 | L79: 2440026
A80: 79 | B80: 1 | C80: 3 | E80: 21 | F80: 199520 | G80: 46739 | H80: 442 | I80: 74455 | J80: 24491973 | K80: 89700 | L80: 2227878
A81: 80 | B81: 1 | C81: 3 | E81: 22 | F81: 199521 | G81: 46740 | H81: 442 | I81: 74456 | J81: 24491974 | K81: 89700 | L81: 2227878
A82: 81 | B82: 1 | C82: 3 | E82: 23 | F82: 199522 | G82: 46741 | H82: 442 | I82: 74457 | J82: 24491975 | K82: 89700 | L82: 2227878
... A120: 119 | B120: 1 | C120: 32 | E120: 4 | F120: 199531 | G120: 46850 | H120: 442 | I120: 74297 | J120: 24495247 | K120: 75114 | L120: 1865606
A121: 120 | B121: 1 | C121: 32 | E121: 5 | F121: 199532 | G121: 6621-9 | H121: 442 | I121: 74298 | J121: 24495251 | K121: 75114 | L121: 1865606
A122: 121 | B122: 1 | C122: 32 | E122: 6 | F122: 199533 | G122: 46851 | H122: 442 | I122: 74299 | J122: 24495455 | K122: 98241 | L122: 2440026
A123: 122 | B123: 1 | C123: 32 | E123: 7 | F123: 199534 | G123: 46852 | H123: 442 | I123: 74300 | J123: 24495488 | K123: 89700 | L123: 2227878
A124: 123 | B124: 1 | C124: 32 | E124: 8 | F124: 199535 | G124: 46853 | H124: 442 | I124: 74301 | J124: 24495492 | K124: 89700 | L124: 2227878
A125: 124 | B125: 1 | C125: 32 | E125: 9 | F125: 199536 | G125: 46854 | H125: 442 | I125: 74302 | J125: 24495498 | K125: 89700 | L125: 2227878
A126: 125 | B126: 1 | C126: 32 | E126: 10 | F126: 199537 | G126: 46855 | H126: 442 | I126: 74303 | J126: 24495502 | K126: 89700 | L126: 2227878
A127: 126 | B127: 1 | C127: 32 | E127: 11 | F127: 199538 | G127: 46856 | H127: 442 | I127: 74304 | J127: 24495507 | K127: 89700 | L127: 2227878
A128: 127 | B128: 1 | C128: 32 | E128: 12 | F128: 199539 | G128: 46857 | H128: 442 | I128: 74305 | J128: 24495509 | K128: 89700 | L128: 2227878
A129: 128 | B129: 1 | C129: 32 | E129: 13 | F129: 199540 | G129: 44934-4 | H129: 442 | I129: 74306 | J129: 24495519 | K129: 89700 | L129: 2227878
A130: 129 | B130: 1 | C130: 32 | E130: 14 | F130: 199541 | G130: 46858 | H130: 442 | I130: 74307 | J130: 24495521 | K130: 89700 | L130: 2227878
A131: 130 | B131: 1 | C131: 32 | E131: 15 | F131: 199542 | G131: 46859 | H131: 442 | I131: 74308 | J131: 24495537 | K131: 98241 | L131: 2440026
A132: 131 | B132: 1 | C132: 32 | E132: 16 | F132: 199543 | G132: 46860 | H132: 442 | I132: 74309 | J132: 24495601 | K132: 75114 | L132: 1865606
...

Sheet Original Lotes a Escriturar
A1: ='Original Lotes Escritura'!A1 -> N° Hugo | B1: ='Original Lotes Escritura'!B1 -> Circunscripción | C1: ='Original Lotes Escritura'!C1 -> Sección | D1: ='Original Lotes Escritura'!D1 -> Manzana | E1: ='Original Lotes Escritura'!E1 -> Parcela | F1: ='Original Lotes Escritura'!F1 -> Partida ARBA | G1: ='Original Lotes Escritura'!G1 -> Partida Municipal | H1: ='Original Lotes Escritura'!H1 -> Escritura | ... L1: ='Original Lotes Escritura'!L1 -> VF al Acto
A2: N° | B2: Circ. | C2: Secc. | D2: Manzana | E2: Parcela | F2: Partida ARBA | G2: Partida Municipal | H2: Escritura | I2: Matrícula | J2: Certificado Catastral | K2: Valor Escritura | L2: Observaciones
A3: 1 | B3: V | C3: F | D3: 96 | E3: 1 | F3: 65900 | G3: 46647-7 | H3: 442 | I3: 107881 | J3: 24505695 | K3: U$S 103.600
A4: 2 | B4: V | C4: F | D4: 96 | E4: 2 | F4: 95572 | G4: 46648-4 | H4: 442 | I4: 107882 | J4: 24505697
A5: 3 | B5: V | C5: F | D5: 96 | E5: 3 | F5: 95573 | G5: 46649-1 | H5: 442 | I5: 107883 | J5: 24505706
A6: 4 | B6: V | C6: F | D6: 96 | E6: 12 | F6: 95582 | G6: 46658-3 | H6: 442 | I6: 30003 | J6: 24505709
A7: 5 | B7: V | C7: F | D7: 96 | E7: 13 | F7: 95583 | G7: 46659-0 | H7: 442 | I7: 107884 | J7: 24505712
A8: 6 | B8: V | C8: F | D8: 96 | E8: 15 | F8: 95585 | G8: 46661-3 | H8: 442 | I8: 107885 | J8: 24505722
A9: 7 | B9: V | C9: F | D9: 96 | E9: 16 | F9: 95586 | G9: 46420-4 | H9: 442 | I9: 107886 | J9: 24505724
A10: 8 | B10: V | C10: F | D10: 96 | E10: 17 | F10: 95587 | G10: 46421-4 | H10: 442 | I10: 107887 | J10: 24505727
A11: 9 | B11: V | C11: F | D11: 96 | E11: 19 | F11: 95589 | G11: 46423-5 | H11: 442 | I11: 107888 | J11: 24505735
A12: 10 | B12: V | C12: F | D12: 96 | E12: 20 | F12: 95590 | G12: 46424-2 | H12: 442 | I12: 107889 | J12: 24505744
A13: 11 | B13: V | C13: F | D13: 96 | E13: 22 | F13: 95592 | G13: 46426-6 | H13: 442 | I13: 107890 | J13: 24505751
A14: 12 | B14: V | C14: F | D14: 96 | E14: 23 | F14: 95593 | G14: 46427-3 | H14: 442 | I14: 74403 | J14: 24505752
A15: 13 | B15: V | C15: F | D15: 96 | E15: 24 | F15: 95594 | G15: 46428-0 | H15: 442 | I15: 107891 | J15: 24505819
... A18: 16 | B18: V | C18: F | D18: 96 | E18: 28 | F18: 95598 | G18: 46431-0 | H18: 442 | I18: 74406 | J18: 24505826
A19: 17 | B19: V | C19: F | D19: 124 | E19: 6 | F19: 96225 | G19: 46466-2 | H19: 442 | I19: 107876 | J19: 24505837 | K19: U$S 41.200
A20: 18 | B20: V | C20: F | D20: 124 | E20: 7 | F20: 96226 | G20: 46467-9 | H20: 442 | I20: 107892 | J20: 24505840
A21: 19 | B21: V | C21: F | D21: 124 | E21: 9 | F21: 96228 | G21: 46469-3 | H21: 442 | I21: 107893 | J21: 24505872
A22: 20 | B22: V | C22: F | D22: 124 | E22: 10 | F22: 96229 | G22: 46470-9 | H22: 442 | I22: 107894 | J22: 24505919
A23: 21 | B23: V | C23: F | D23: 124 | E23: 11 | F23: 96230 | G23: 46471-6 | H23: 442 | I23: 107895 | J23: 24505923
A24: 22 | B24: V | C24: F | D24: 124 | E24: 12 | F24: 96231 | G24: 46472-3 | H24: 442 | I24: 107896 | J24: 24505933
A25: 23 | B25: V | C25: F | D25: 124 | E25: 13 | F25: 96232 | G25: 46473-0 | H25: 442 | I25: 107897 | J25: 24505943
A26: 24 | B26: V | C26: F | D26: 124 | E26: 14 | F26: 96233 | G26: 46474-7 | H26: 442 | I26: 107898 | J26: 24505947
A27: 25 | B27: V | C27: F | D27: 124 | E27: 15 | F27: 96234 | G27: 46475-4 | H27: 442 | I27: 107899 | J27: 24505959
A28: 26 | B28: V | C28: F | D28: 124 | E28: 16A | F28: 96235 | G28: 46476-1 | H28: 442 | I28: 107900 | J28: 24505985
A29: 27 | B29: V | C29: F | D29: 124 | E29: 17A | F29: 96236 | G29: 46477-8 | H29: 442 | I29: 107901 | J29: 24505998
A30: 28 | B30: V | C30: F | D30: 124 | E30: 18A | F30: 96237 | G30: 46478-5 | H30: 442 | I30: 107903 | J30: 24506003
A31: 29 | B31: V | C31: F | D31: 124 | E31: 19A | F31: 96238 | G31: 46479-2 | H31: 442 | I31: 107904 | J31: 24506007
A32: 30 | B32: V | C32: F | D32: 124 | E32: 20A | F32: 96238 | G32: 46480-8 | H32: 442 | I32: 107905 | J32: 24506053
A33: 31 | B33: V | C33: F | D33: 124 | E33: 21A | F33: 96240 | G33: 46481-5 | H33: 442 | I33: 107906 | J33: 24506058
A34: 32 | B34: V | C34: F | D34: 124 | E34: 22A | F34: 96241 | G34: 46482-2 | H34: 442 | I34: 107907 | J34: 24506061
A35: 33 | B35: V | C35: F | D35: 124 | E35: 23A | F35: 96242 | G35: 46483-9 | H35: 442 | I35: 107908 | J35: 24506066
A36: 34 | B36: V | C36: F | D36: 124 | E36: 24 | F36: 96243 | G36: 46484-6 | H36: 442 | I36: 107910 | J36: 24506071
A37: 35 | B37: V | C37: F | D37: 124 | E37: 25 | F37: 96244 | G37: 46485-3 | H37: 442 | I37: 107911 | J37: 24506076
A38: 36 | B38: V | C38: F | D38: 124 | E38: 27 | F38: 96246 | G38: 46487-7 | H38: 442 | I38: 107912 | J38: 24506086
A39: 37 | B39: V | C39: F | D39: 124 | E39: 28 | F39: 96247 | G39: 46488-4 | H39: 442 | I39: 107914 | J39: 24506107
A40: 38 | B40: V | C40: F | D40: 124 | E40: 29 | F40: 96248 | G40: 46489-1 | H40: 442 | I40: 107915 | J40: 24506173
A41: 39 | B41: V | C41: F | D41: 124 | E41: 30 | F41: 96249 | G41: 46490-7 | H41: 442 | I41: 107916 | J41: 24506186
A42: 40 | B42: V | C42: F | D42: 125 | E42: 1 | F42: 67428 | G42: 6678 | H42: 442 | I42: 107917 | J42: 24506277 | K42: U$S 45.040
...

Sheet Original Resumen por Manzana AE
A1: Manzana | B1: Cantidad Lotes | C1: Valor Escritura
A2: 96 | B2: 16 | C2: U$S 103.600
A3: 124 | B3: 23 | C3: U$S 41.200
A4: 125 | B4: 28 | C4: U$S 45.040
A5: 126 | B5: 27 | C5: U$S 122.400
A6: 156 | B6: 27 | C6: U$S 85.840
A7: TOTAL | B7: =SUM(B2:B6) -> 121
